truncating documents...: 0it [00:00, ?it/s]truncating documents...: 17it [00:00, 167.84it/s]truncating documents...: 66it [00:00, 354.71it/s]truncating documents...: 120it [00:00, 438.67it/s]truncating documents...: 169it [00:00, 458.64it/s]truncating documents...: 217it [00:00, 466.15it/s]truncating documents...: 271it [00:00, 489.72it/s]truncating documents...: 320it [00:00, 459.19it/s]truncating documents...: 376it [00:00, 489.28it/s]truncating documents...: 426it [00:00, 484.58it/s]truncating documents...: 475it [00:01, 483.76it/s]truncating documents...: 524it [00:01, 483.76it/s]truncating documents...: 577it [00:01, 497.16it/s]truncating documents...: 632it [00:01, 509.62it/s]truncating documents...: 685it [00:01, 509.10it/s]truncating documents...: 738it [00:01, 514.44it/s]truncating documents...: 808it [00:01, 568.53it/s]truncating documents...: 891it [00:01, 641.46it/s]truncating documents...: 972it [00:01, 690.06it/s]truncating documents...: 1000it [00:01, 531.94it/s]
Traceback (most recent call last):
  File "/home/woodygan/.conda/envs/dpicl/lib/python3.8/site-packages/huggingface_hub/utils/_errors.py", line 304, in hf_raise_for_status
    response.raise_for_status()
  File "/home/woodygan/.conda/envs/dpicl/lib/python3.8/site-packages/requests/models.py", line 1024, in raise_for_status
    raise HTTPError(http_error_msg, response=self)
requests.exceptions.HTTPError: 403 Client Error: Forbidden for url: https://huggingface.co/meta-llama/Meta-Llama-3.1-8B-Instruct/resolve/main/config.json

The above exception was the direct cause of the following exception:

Traceback (most recent call last):
  File "/home/woodygan/.conda/envs/dpicl/lib/python3.8/site-packages/transformers/utils/hub.py", line 402, in cached_file
    resolved_file = hf_hub_download(
  File "/home/woodygan/.conda/envs/dpicl/lib/python3.8/site-packages/huggingface_hub/utils/_deprecation.py", line 101, in inner_f
    return f(*args, **kwargs)
  File "/home/woodygan/.conda/envs/dpicl/lib/python3.8/site-packages/huggingface_hub/utils/_validators.py", line 114, in _inner_fn
    return fn(*args, **kwargs)
  File "/home/woodygan/.conda/envs/dpicl/lib/python3.8/site-packages/huggingface_hub/file_download.py", line 1240, in hf_hub_download
    return _hf_hub_download_to_cache_dir(
  File "/home/woodygan/.conda/envs/dpicl/lib/python3.8/site-packages/huggingface_hub/file_download.py", line 1347, in _hf_hub_download_to_cache_dir
    _raise_on_head_call_error(head_call_error, force_download, local_files_only)
  File "/home/woodygan/.conda/envs/dpicl/lib/python3.8/site-packages/huggingface_hub/file_download.py", line 1855, in _raise_on_head_call_error
    raise head_call_error
  File "/home/woodygan/.conda/envs/dpicl/lib/python3.8/site-packages/huggingface_hub/file_download.py", line 1752, in _get_metadata_or_catch_error
    metadata = get_hf_file_metadata(
  File "/home/woodygan/.conda/envs/dpicl/lib/python3.8/site-packages/huggingface_hub/utils/_validators.py", line 114, in _inner_fn
    return fn(*args, **kwargs)
  File "/home/woodygan/.conda/envs/dpicl/lib/python3.8/site-packages/huggingface_hub/file_download.py", line 1674, in get_hf_file_metadata
    r = _request_wrapper(
  File "/home/woodygan/.conda/envs/dpicl/lib/python3.8/site-packages/huggingface_hub/file_download.py", line 376, in _request_wrapper
    response = _request_wrapper(
  File "/home/woodygan/.conda/envs/dpicl/lib/python3.8/site-packages/huggingface_hub/file_download.py", line 400, in _request_wrapper
    hf_raise_for_status(response)
  File "/home/woodygan/.conda/envs/dpicl/lib/python3.8/site-packages/huggingface_hub/utils/_errors.py", line 321, in hf_raise_for_status
    raise GatedRepoError(message, response) from e
huggingface_hub.utils._errors.GatedRepoError: 403 Client Error. (Request ID: Root=1-66e7589e-2a0b44b86a4af5907c79fff9;74e80c95-d599-494f-b8fc-c3fe5dec5a20)

Cannot access gated repo for url https://huggingface.co/meta-llama/Meta-Llama-3.1-8B-Instruct/resolve/main/config.json.
Your request to access model meta-llama/Meta-Llama-3.1-8B-Instruct is awaiting a review from the repo authors.

The above exception was the direct cause of the following exception:

Traceback (most recent call last):
  File "dpicl.py", line 220, in <module>
    pipeline = transformers.pipeline(
  File "/home/woodygan/.conda/envs/dpicl/lib/python3.8/site-packages/transformers/pipelines/__init__.py", line 805, in pipeline
    config = AutoConfig.from_pretrained(
  File "/home/woodygan/.conda/envs/dpicl/lib/python3.8/site-packages/transformers/models/auto/configuration_auto.py", line 976, in from_pretrained
    config_dict, unused_kwargs = PretrainedConfig.get_config_dict(pretrained_model_name_or_path, **kwargs)
  File "/home/woodygan/.conda/envs/dpicl/lib/python3.8/site-packages/transformers/configuration_utils.py", line 632, in get_config_dict
    config_dict, kwargs = cls._get_config_dict(pretrained_model_name_or_path, **kwargs)
  File "/home/woodygan/.conda/envs/dpicl/lib/python3.8/site-packages/transformers/configuration_utils.py", line 689, in _get_config_dict
    resolved_config_file = cached_file(
  File "/home/woodygan/.conda/envs/dpicl/lib/python3.8/site-packages/transformers/utils/hub.py", line 420, in cached_file
    raise EnvironmentError(
OSError: You are trying to access a gated repo.
Make sure to have access to it at https://huggingface.co/meta-llama/Meta-Llama-3.1-8B-Instruct.
403 Client Error. (Request ID: Root=1-66e7589e-2a0b44b86a4af5907c79fff9;74e80c95-d599-494f-b8fc-c3fe5dec5a20)

Cannot access gated repo for url https://huggingface.co/meta-llama/Meta-Llama-3.1-8B-Instruct/resolve/main/config.json.
Your request to access model meta-llama/Meta-Llama-3.1-8B-Instruct is awaiting a review from the repo authors.
